Workbook

Sheet Summary
C4: KPI Definition | S4: 45036 | V4: Comments/ Hints for KPI Owners:
D6: KPI ID | G6: 5.8.01 | I6: KPI Name | J6: Number of Major Incidents | N6: KPI Owner | P6: Tarek Ben Hnia | V6: - KPI ID/ KPI Name/ KPI Dimension are filled by IT Cost Management - All further values need to be filled by KPI Owner, who is defined by Process Owner - In case of questions/ ambiguities regarding any values / information requested in the KPI Definition section refer to IT Cost Management - KPI Definition including the KPI Target Value can be adjusted if reasonable. Adjustment proposal incl. explanation to be requested by KPI Owner and addressed to IT Cost Management. Proposal will be discussed and approved/ denied by Balance Scorecard Board.
D8: Current KPI Value | G8: {=INDEX(History!E:E,MAX(ISNUMBER(History!E4:E56)*ROW(History!E4:E56)))} -> 9.1666667 | I8: Target KPI | J8: ≤ 7 | N8: KPI Dimension | P8: Customer
D10: KPI Description | G10: Starting from 01/23: KPI=The average number of major IT incidents occurred monthly over the last 12 calendar months. Before 01/23: Total number of major IT incidents occurred within last calendar month | N10: KPI Objectives | P10: Support 1.1. & 1.2 Strategic Goals
N11: main purpose(s) of the KPI
D15: KPI reference date | G15: 43570 | I15: - All KPIs are to be reported monthly - | N15: KPI Drivers | P15: - Proper handover to operations - Clear responsibilities - Process conformance - adequate resource allocation/ technical operational service
D16: Exact day of KPI evaluation. Format: dd.mm.yyyy. e.g. 6th day of each month. | N16: main factors of influence for the KPI
G17: Describe within the KPI description or under Further remarks earliest possible evaluation date and if the KPI is updated and can be evaluated after this date within the same reporting month.
D21: KPI calculation logic | G21: Starting from 01/23: KPI=The average number of major IT incidents occurred monthly over last 12 calendar months. Monthly evaluation: Total number of major IT incidents occurred within last calendar month. Before 01/23: KPI=Total number of major IT incidents occurred within last calendar month. Incidents are identified automatically based on defined criteria, see below. | N21: Data Source/ Data Owner | P21: ITSM Tool, currently ServiceNow Data Owner: Incident Manager
D26: KPI Target Value | G26: Total number of major IT incidents per calendar month ≤ 7 | N26: KPI recipients outside of BSC? | P26: not defined yet
D29: Explanation of used/ relevant definitions | G29: Major incident and other definitions will be reviewed and if needed (re) defined within FIT program. Current definition within (ServiceNow) is based on following criteria: Request type is Incident AND Priority is Critical AND Major Incident state = Accepted | N29: Further remarks | P29: Earliest possible KPI evaluation after month end
V39: Comments/ Hints for KPI Owners:
V40: chart is created by IT Cost Management
C71: KPI Comments & Actions | V71: Comments/ Hints for KPI Owners:
D73: KPI Owner Status Comment | K73: Corrective Actions | V73: - KPI Owner comments monthly, according to the reporting due date, the current KPI Status - KPI Owner names the main reasons for KPI Target deviations in the section "Root Cause" - In the section Open actions KPI Owner suggests corrective actions to improve KPI performance/ to achieve KPI Target - Suggested corrective actions including Responsible person will be approved/ redefined/ determined by Balance Scorecard Board - Progress of approved corrective actions will be tracked monthly: Open actions remain in the section open actions, current status to be provided to IT Cost Management. Actions, which are closed between last- and current BSC reporting to be moved to the section Closed actions. All previously closed actions will be removed from BSC for current reporting month. History to be tracked by IT Cost Management (each report will be archived) - KPI Definition including the KPI Target Value can be adjusted if reasonable, see above.
D74: Major Incidents this month are impacting the Data Center, we continue Firewall issues leading complete site disruptions. Incidents caused by Problems, we should continue align best practices of Problem Management Process and act to before incidents occur | K74: Open actions: | Q74: Root Cause # | R74: Due Date | S74: Responsible
K75: #1: | L75: Align with Change Management process & regulations | Q75: 1 | R75: 45107 | S75: Change Manager - K.Shkromyda
K76: #2: | L76: Align with Problem Management process & regulations | Q76: 2 | R76: 45107 | S76: Problem Manager - L.Moroyoqui
K77: #3:
K78: #4:
K79: #5:
K80: #6:
D81: Root Cause
D82: # 1: | E82: Issues caused by Changes request | K82: Closed actions: | Q82: Root Cause # | R82: Closure Date | S82: Responsible
D83: # 2: | E83: Firewall malfunction leading complete site interruptions | K83: #1
D84: # 3: | K84: #2:
D85: # 4: | K85: #3:
D86: # 5: | K86: #4:
D87: # 6:
D88: # 7:
D93: # 6:

Sheet History
A2: Quantity of IT Major Incidents
C4: Target KPI | D4: Current month | E4: Ø Last 12 months | F4: Actual over of Target | G4: Actual KPI LTM | H4: Comments for KPI Target adjustments
B5: 42736 | C5: 5 | D5: 1
B6: 42767 | C6: 5 | D6: 4
B7: 42795 | C7: 5 | D7: 10
B8: 42826 | C8: 5 | D8: 8
B9: 42856 | C9: 5 | D9: 10
B10: 42887 | C10: 5 | D10: 9
B11: 42917 | C11: 5 | D11: 3
B12: 42948 | C12: 5 | D12: 11
B13: 42979 | C13: 5 | D13: 5
B14: 43009 | C14: 5 | D14: 2
B15: 43040 | C15: 5 | D15: 6
B16: 43070 | C16: 5 | D16: 5
... B41: 44584 | C41: 7 | D41: 5
B42: 44615 | C42: 7 | D42: 7 | E42: =AVERAGE(D31:D42) -> 7.5833333
B43: 44646 | C43: 7 | D43: 6 | E43: =AVERAGE(D32:D43) -> 7.1666667
B44: 44677 | C44: 7 | D44: 6 | E44: =AVERAGE(D33:D44) -> 6.9166667
B45: 44708 | C45: 7 | D45: 8 | E45: =AVERAGE(D34:D45) -> 6.8333333
B46: 44739 | C46: 7 | D46: 8 | E46: =AVERAGE(D35:D46) -> 6.6666667
B47: 44770 | C47: 7 | D47: 8 | E47: =AVERAGE(D36:D47) -> 6.8333333
B48: 44801 | C48: 7 | D48: 5 | E48: =AVERAGE(D37:D48) -> 6.6666667
B49: 44832 | C49: 7 | D49: 8 | E49: =AVERAGE(D38:D49) -> 6.8333333
B50: 44863 | C50: 7 | D50: 13 | E50: =AVERAGE(D39:D50) -> 7.5833333
B51: 44894 | C51: 7 | D51: 6 | E51: =AVERAGE(D40:D51) -> 7.1666667
B52: 44925 | C52: 7 | D52: 8 | E52: =AVERAGE(D41:D52) -> 7.3333333
B53: 44956 | C53: 7 | D53: 11 | E53: =AVERAGE(D41:D53) -> 7.6153846
B54: 44977 | C54: 7 | D54: 9 | E54: =AVERAGE(D43:D54) -> 8
B55: 45005 | C55: 7 | D55: 14 | E55: =AVERAGE(D43:D55) -> 8.4615385
B56: 45036 | C56: 7 | D56: 12 | E56: =AVERAGE(D45:D56) -> 9.1666667
B63: IT Services by Service Catalog 2.0
C64: Target KPI | D64: Current Month | E64: Actual on Target | F64: Actual over of Target
B65: Total | C65: 7 | D65: =SUM(D66:D82) -> 12 | E65: =IF(D65>C65,C65,D65) -> 7 | F65: =IF(D65>E65,D65-E65,"") -> 5
B66: Supply Chain Management | C66: 7 | D66: =COUNTIF(Data!E:G,H66) -> 2 | E66: =IF(D66>C66,C66,D66) -> 2 | F66: =IF(D66>E66,D66-E66,"") | H66: Supply Chain Management (SCM)
B67: Manufacturing Execution | C67: 7 | D67: =COUNTIF(Data!E:G,H67) -> 0 | E67: =IF(D67>C67,C67,D67) -> 0 | F67: =IF(D67>E67,D67-E67,"") | H67: Manufacturing Execution (MES)
B68: Product Lifecycle Management | C68: 7 | D68: =COUNTIF(Data!E:G,H68) -> 0 | E68: =IF(D68>C68,C68,D68) -> 0 | F68: =IF(D68>E68,D68-E68,"") | H68: Product Lifecycle Management (PLM)
B69: Customer Relationship Management | C69: 7 | D69: =COUNTIF(Data!E:G,H69) -> 0 | E69: =IF(D69>C69,C69,D69) -> 0 | F69: =IF(D69>E69,D69-E69,"") | H69: Customer Relationship Management (CRM)
B70: Business Intelligence | C70: 7 | D70: =COUNTIF(Data!E:G,H70) -> 0 | E70: =IF(D70>C70,C70,D70) -> 0 | F70: =IF(D70>E70,D70-E70,"") | H70: Business Intelligence (BI)
B71: Finance & Controlling | C71: 7 | D71: =COUNTIF(Data!E:G,H71) -> 0 | E71: =IF(D71>C71,C71,D71) -> 0 | F71: =IF(D71>E71,D71-E71,"") | H71: Finance & Controlling (FICO)
B72: Human Resources | C72: 7 | D72: =COUNTIF(Data!E:G,H72) -> 0 | E72: =IF(D72>C72,C72,D72) -> 0 | F72: =IF(D72>E72,D72-E72,"") | H72: Human Resources (HR)
...

Sheet Data
A1: Number | B1: State | C1: Priority | D1: Affected Service | E1: Parent | F1: Parent | G1: Service Owner | H1: Configuration item | I1: Location | J1: Description | K1: Short description | L1: Opened | M1: Resolution code | N1: Resolution notes | O1: Responsible group | P1: Responsible user | Q1: Resolved | R1: Reopen count | S1: Caller | T1: Aging Group | U1: Duration | V1: Service classification | W1: Business duration | X1: Problem | Y1: SLA | Z1: Schedule | AA1: Location Division | AB1: Parent Incident | AC1: Service Request
A2: INC0122254 | B2: Resolved | C2: 1 - Critical | D2: Data Center & Cloud Network | E2: Data Center | F2: Network & Server Infra | G2: Benjamin Meier | I2: WRSPR | J2: Non functioning access to internet for all end users (WRSPR) Thanks in advance Ivan | K2: Non functioning access to internet for all end users (WRSPR) | L2: 45019.348 | M2: Solved (Permanently) | N2: One of our central user-id firewalls vuhv1pauid03 did not work correctly. The firewall did also no failover. After manual failover to vunrzpauid03 everything worked again. Monitoring for the User-ID connection is also not configured in PRTG. We opened also a ticket to Palo to verify the root cause. Problem ticket will be created. | O2: 3rd - Network & Connectivity Security | P2: Benjamin Besslein | Q2: 45019.466 | R2: 0 | S2: Ivan Radosavljevic | T2: > 30 & < 60 Days | U2: 10206 | V2: Service Component | W2: 10206 | X2: PRB0040711 | Y2: Leo Profile 1 SLA | Z2: Leo On-Call Support (Mon-Sun 0:00-24:00 CET) | AA2: WSD
A3: INC0122703 | B3: Resolved | C3: 1 - Critical | D3: Data Center & Cloud Network | E3: Data Center | F3: Network & Server Infra | G3: Benjamin Meier | I3: CHUHA | J3: Dear Colleagues, Since 5 pm the connection between plant LKH Hungary and the corporate network is broken. Locally everything seems to be ok, internet provider didn’t report any issue. Could you please check and fix the problem? It’s urgent as the plant’s work is impacted seriously by this issue! Thank you in advance and looking forward to your soon response! Zoltan Tobias | K3: No connection to the center | L3: 45022.724 | M3: Solved (Permanently) | N3: Reboot the Palo Alto 2 because was the only devices that was not reporting communication. After that all service came up and communication was reestablished. | O3: 2nd - Network & Connectivity | P3: Roberto Hugo Santiago Dominguez | Q3: 45022.791 | R3: 0 | S3: Zoltan Tobias | T3: < 30 Days | U3: 5758 | V3: Service Component | W3: 5758 | Y3: Leo Profile 1 SLA | Z3: Leo On-Call Support (Mon-Sun 0:00-24:00 CET) | AA3: WCS - BG AM
A4: INC0122776 | B4: Resolved | C4: 1 - Critical | D4: Plant & Office Network (LAN) | E4: Network & Connectivity | F4: Network & Server Infra | G4: Stefan Sawluk | I4: CDEFZ | K4: we are not able to reach any services outside (v center ....) | L4: 45024.654 | M4: Solved (Work Around) | N4: Onsite in Roth: Checked the Backbone and Aggregation Switches. On BB the Port-Channel to the Aggregation was missing. No configuration. Added Po12 and configured the Interface 1/2 on both switches. VLAN 997 and 998 was missing on AGG01 and AGG02. Added VLANs. Configuration is saved. Network recovered. | O4: 3rd - Network & Connectivity | P4: Stefan Sawluk | Q4: 45026.481 | R4: 0 | S4: Oliver Ludwig | T4: < 30 Days | U4: 157863 | V4: Service Component | W4: 157863 | Y4: Leo Profile 1 SLA | Z4: Leo On-Call Support (Mon-Sun 0:00-24:00 CET) | AA4: WCS - BG AM
A5: INC0122852 | B5: Closed | C5: 1 - Critical | D5: Visual Logistics: SD | E5: Visual | F5: Supply Chain Management (SCM) | G5: Juan Francisco Rosas Corbala | I5: WMXHE | J5: Visual ERP is not available / costing task may still be running... Please help us to solve this. Thank you | K5: Visual is not Available - EDI Transmission with customers is not possible | L5: 45027.07 | M5: Solved (Permanently) | N5: root cause:Weekly Visual jobs (MRP and Cost Rollup) were running at the same time, causing a database deadlock. solution: running mrp manual. and next steps: costing will be running on sunday | O5: 3rd - Local Apps Americas | P5: Jose Elias Valenzuela Valenzuela | Q5: 45027.882 | R5: 0 | S5: Arturo Beltran Alcaide | T5: < 30 Days | U5: 70156 | V5: Service Module | W5: 70156 | Y5: Leo Profile 1 SLA | Z5: Leo On-Call Support (Mon-Sun 0:00-24:00 CET) | AA5: WSD
A6: INC0123075 | B6: Resolved | C6: 1 - Critical | D6: Palo Alto Firewall | E6: Network & Connectivity Security - DC | F6: Data Center | G6: Andreas Thanner | I6: WROAR | J6: Hello, RO8 it`s down, please check. | K6: Hello, RO8 it`s down, please check. | L6: 45028.436 | M6: Solved (Work Around) | N6: vuro8pa01 is suspended. further troubleshooting could be found in PRB0040670 | O6: 2nd - Network & Connectivity Security | P6: Riheb Chabbah | Q6: 45028.578 | R6: 0 | S6: Carmen Mirela Brata | T6: < 30 Days | U6: 12224 | V6: Service Module | W6: 12224 | X6: PRB0040670 | Y6: Leo Profile 1 SLA | Z6: Leo Default Support Hours (Mon-Fri 8:00-17:00 CET) | AA6: WSD
A7: INC0123161 | B7: Resolved | C7: 1 - Critical | D7: Data Center & Cloud Network | E7: Data Center | F7: Network & Server Infra | G7: Benjamin Meier | I7: WMXHE | J7: Hello Colleagues, Can you please check the network between LEONI to SAP systems allocated in the Cloud HEC. All users cannot connect to any SAP application hosted in the Cloud. For on-premise SAP System the connections is working well. I.E Hostname: vhleop01cs.hec.leoni.local I tried to ping with no success: C:\Users\rufe5003>ping vhleop01cs.hec.leoni.local Pinging vhleop01cs.fra3.hec.leoni.local [10.217.12.229] with 32 bytes of data: Request timed out. Request timed out. Request timed out. Request timed out. Ping statistics for 10.217.12.229: Packets: Sent = 4, Received = 0, Lost = 4 (100% loss), C:\Users\rufe5003> Attached error message | K7: There is no connection to any SAP systems hosted on the HEC | L7: 45028.864 | M7: Solved (Permanently) | N7: While working on a CHG0045243 to reroute Client VPN connections within EMEA we experienced that some of our Site 2 Tunnels (including them used for the connection described in this incident) were in an half-open state. We were forced to re-initiate those tunnels and can confirm that connecticity is given again. | O7: 3rd - Network & Connectivity Security | P7: Andreas Thanner | Q7: 45028.896 | R7: 0 | S7: Felipe Rueda Gutierrez | T7: < 30 Days | U7: 2725 | V7: Service Component | W7: 2725 | Y7: Leo Profile 1 SLA | Z7: Leo On-Call Support (Mon-Sun 0:00-24:00 CET) | AA7: WSD
A8: INC0123290 | B8: Closed | C8: 1 - Critical | D8: EDI (Axway, Seeburger, SFX) | E8: Data Distribution & Archive | F8: Support Applications | G8: Thomas Grieser | I8: WMXME | J8: Demand from CAT cannot be processed into SAP WP1 or Visual, cumulative qty is showing empty | K8: Demand from CAT cannot be processed into SAP WP1 or Visual | L8: 45029.903 | M8: Solved (Work Around) | N8: SAP WP1 & Visual are currently in normal operational state, all record were reprocessed correctly. | O8: 2nd - EDI | P8: Adam Hogin | Q8: 45030.142 | R8: 0 | S8: Juan Antonio Moreno Cobos | T8: < 30 Days | U8: 20672 | V8: Service Component | W8: 0 | Y8: Leo Profile 1 SLA | Z8: Leo Default Support Hours (Mon-Fri 8:00-17:00 CET) | AA8: WSD
A9: INC0123688 | B9: Resolved | C9: 1 - Critical | D9: Palo Alto Firewall | E9: Network & Connectivity Security - DC | F9: Data Center | G9: Stefan Sawluk | I9: CCNCA | J9: Hello Colleagues In CNA , from 04:07 2023/04/19 up to now, all labels can't be printed out from OMS server , this cause our production business disturbed , pls solve it a.s.a.p! | K9: Hello Colleagues In CNA , from 04:07 2023/04/19 up to now, all labels can't be printed out from OMS server , this cause our production business disturbed , pls | L9: 45034.99 | M9: Solved (Work Around) | N9: Incident has been solved, root cause will be follow under the problem number:PRB0040727 | O9: 2nd - Network & Connectivity | P9: Roberto Hugo Santiago Dominguez | Q9: 45035.099 | R9: 0 | S9: Felix Shen | T9: < 30 Days | U9: 9387 | V9: Service Component | W9: 9387 | X9: PRB0040727 | Y9: Leo Profile 1 SLA | Z9: Leo On-Call Support (Mon-Sun 0:00-24:00 CET) | AA9: WCS - BG AM
A10: INC0123808 | B10: Closed | C10: 1 - Critical | D10: Linux / Unix | E10: Server | F10: Data Center | G10: Armin Loehr | I10: HDENM | J10: Hello, since yesterday from 11pm the SFTP connection to sapfsp.leoni.local no longer works. Therefore, all interfaces with the SFTP from the SAP PO (PP3) no longer work. Regards, Truong | K10: Hello, since yesterday from 11pm the SFTP connection to sapfsp.leoni.local no longer works. Therefore, all interfaces with the SFTP from the SAP PO (PP3) no | L10: 45035.577 | M10: Solved (Work Around) | N10: The HEC Fileserver sapfsp.leoni.local has been rebooted. Root cause analysis is still ongoing. | O10: 3rd - LINUX/UNIX Server | P10: Andreas Zierott | Q10: 45035.947 | R10: 0 | S10: Anh Truong Hoang | T10: < 30 Days | U10: 31979 | V10: Service Module | W10: 11378 | X10: PRB0040730 | Y10: Leo Profile 1 SLA | Z10: Leo Default Support Hours (Mon-Fri 8:00-17:00 CET) | AA10: Holding
A11: INC0124069 | B11: Closed | C11: 1 - Critical | D11: SAP GTS: System Administration | E11: SAP GTS | F11: Supply Chain Management (SCM) | G11: Daniel Maurer | I11: CHUHA | J11: Dear All, Our colleague from the logistic area noticed a problem in connection with GTP-GTS system. They cannot take out materials from the storage. Can you check it please? Thanks for your support, Mátyás Mizser LKH LEONI Kft. | K11: GTP - GTS not available | L11: 45037.847 | M11: Solved (Work Around) | N11: In agreement with Mrs. Tigges, I request to restart the whole System GTP (application and Tenant Database) in SAP Ticket: "11255 / 2023 GTPLEO || system is down". Checks in the systems already sent below by Mrs. Tigges. At this moment the caller confirm they can take out materials from the storage. For detailed information I attached the SAP Ticket, we are still waiting for the RCA from SAP ECS. | O11: 3rd - SAP GTS | P11: Jutta Tigges | Q11: 45038.019 | R11: 0 | S11: Matyas Mizser | T11: < 30 Days | U11: 14868 | V11: Service Module | W11: 0 | X11: PRB0040732 | Y11: Leo Profile 1 SLA | Z11: Leo Default Support Hours (Mon-Fri 8:00-17:00 CET) | AA11: WCS - BG AM
A12: INC0124644 | B12: Resolved | C12: 1 - Critical | D12: VMware | E12: Site Server | F12: Data Center | G12: Armin Loehr | I12: CMXCU | J12: I attach the image of the error when trying to start the server svmx1file01 | K12: svmx1file01 after a reboot the server does not find the ip | L12: 45043.992 | M12: Solved (Permanently) | N12: Still investigating why server restarted automatically. Problem PRB0040735 has been created to follow up. Full VM has been restored. | O12: 2nd - Virtualization | P12: Ricardo Rico Montano | Q12: 45044.295 | R12: 0 | S12: Marco Hernandez | T12: < 30 Days | U12: 26201 | V12: Service Module | W12: 0 | X12: PRB0040735 | Y12: Leo Profile 1 SLA | Z12: Leo Default Support Hours (Mon-Fri 8:00-17:00 CET) | AA12: WCS - BG AM
A13: INC0124722 | B13: Resolved | C13: 1 - Critical | D13: VMware | E13: Site Server | F13: Data Center | G13: Armin Loehr | I13: WCNJN | J13: hello our host excnjvpc03 now can't start and meet an error. can you pls help us to check this issue asap. thank you very much. | K13: excnjvpc03 can't start and meet an error | L13: 45045.403 | M13: Solved (Permanently) | N13: due to Kernel error so the esxi is coorupted. - excnjvpc03 esxi is restored with same configuration setup -add to vsan cluster -add to Dswitch -check cnj-hybrid datstore health -check vsna cluster health best regards, ilyes | O13: 2nd - Virtualisation - On Call | P13: Ilyess Lagha | Q13: 45046.012 | R13: 0 | S13: Yuan Xu | T13: < 30 Days | U13: 52658 | V13: Service Module | W13: 0 | Y13: Leo Profile 1 SLA | Z13: Leo Default Support Hours (Mon-Fri 8:00-17:00 CET) | AA13: WSD

Sheet Information
A1: LEONI - IT Operations - IT Service Delivery
A4: Business Service | B4: Major Incidents | C4: Frequency | D4: Related To Process | E4: Root Cause | F4: Corrective Actions (with Due Date & Responsible) | G4: Comments (if available)
D5: Problem
A6: Data Center | B6: 5 | C6: 3 - Regularly | D6: 4 - Problem Management | E6: Firewall malfunction leading complete site interruptions | F6: Problem in Progress
A7: Data Center | B7: 1 | C7: 3 - Regularly | D7: 2 - Change Management | E7: Issues caused by change request | F7: Align with Change Management process & regulations
A8: Data Center | B8: 1 | C8: 3 - Regularly | D8: 4 - Problem Management | E8: Patches wronly applied
A9: Data Center | B9: 1 | C9: 3 - Regularly | D9: 5 - Continuity Management | E9: Power outage | F9: Monitor power batteries are working properly
A10: Network & Connectivity | B10: 1 | C10: 4 - Constantly | D10: 5 - Continuity Management | E10: Issue caused by misconfiguration on back bones | F10: Check with Service Owner for corrective actions
A11: Data Distribution & Archive | B11: 1 | C11: 2 - Periodically | D11: 4 - Problem Management | E11: Issue caused due to the fact the customer sent decimal in the CUM QTY and LAST QTY REC fields
A12: Supply Chain Management (SCM) | B12: 1 | C12: 3 - Regularly | D12: 2 - Change Management | E12: Weekly Visual jobs (MRP and Cost Rollup) were running at the same time, causing a database deadlock. | F12: Align with Change Management process & regulations
A13: Supply Chain Management (SCM) | B13: 1 | C13: 3 - Regularly | D13: 4 - Problem Management | E13: System availability was affected due to unexpected host reboot on the database host server at Azure (SAP HEC) | F13: Problem in Progress
A21: Total | B21: =SUMIFS(B6:B16,B6:B16,">0",C6:C16,"<>1 - Rarely") -> 12
A23: Frequency Scale | B23: Report in KPI | D23: Related To Process
A24: 1 - Rarely | B24: No | D24: 1 - Incident Management
A25: 2 - Periodically | B25: Yes | D25: 2 - Change Management
A26: 3 - Regularly | B26: Yes | D26: 3 - Event Management
A27: 4 - Constantly | B27: Yes | D27: 4 - Problem Management
D28: 5 - Continuity Management

Sheet Corrective Actions
A1: LEONI - IT Operations - IT Service Delivery
A2: Corrective Actions
B5: Corrective Actions
B6: Open actions: | H6: Root Cause # | I6: Due Date | J6: Responsible | K6: Updates | L6: Root Cause description
B7: #1 | C7: Migrate all sites to SDWAN | H7: June22#2 | I7: 45076 | J7: Stefan Sawluk | K7: 03.08: Due date postonement 30.07 => 31.12.2022 15.02.23: Due date 31.12 => 31.03.23 | L7: A bug in this model of routers. This caused that rtnrzvpn01 and rthv1vpn01 lost default route from swgblwan01 that shares via EIGRP
B8: #2 | C8: Rollout of Greylog for all VMs | H8: June22#4 | I8: 45107 | J8: Armin Loehr | K8: 01.09.2022 Change CHG0041597 still in Scheduled state 01.10.2022 Change CHG0041597 still in Scheduled state 11.01.2022 Change CHG0041597 still in Scheduled state 12.01.2022 Change CHG0041597 still in Scheduled state 01.01.2023 Change CHG0041597 still in Scheduled state 01.02.2023 Change CHG0041597 still in Scheduled state 03.07.2023 Change CHG0041597 still in Scheduled state | L8: The real root-cause cannot be analysed any more as the important logs were already rotated. The nearest cause to the incident that is clearly visible is, that the connection to the datastore was lost and thus the server was shutdown.
B9: #3 | C9: Moving to our new Layer3 Design (incl. SD-WAN and DIA). - CHG0042024 | H9: Aug22#2 | I9: 45107 | J9: Riadh Trabelsi | K9: 01.11.2022 Change CHG0042024 in "New" state 01.01.2023 Change CHG0042024 in "New" state 01.02.2023 Change CHG0042024 in "New" state 03.07.2023 Change CHG0042024 in "New" state | L9: Device = vuhv1sapfi01-B connected in UCS-FI-6332-16UP was looping the network causing network issue. VM cluster migration was done during German time. Related to change CHG0039744/ RITM0239106
B10: #4 | C10: Corrective action have to be followed by PRB0040444 | H10: Sep22#2 | I10: 44742 | J10: Angel Lopez | K10: 01.12.2022 Change PRB0040444 still in Assess state 01.01.2023 Change PRB0040444 still in RCA state 03.07.2023 PRB0040444 in Root Cause Analysis | L10: LDAP server “LEO Computer import T2-Leoni“ configured on Leoni changed the status field to Retired, so all the information was updated on ServiceNow. Then “LEO Computer Import from AD” created new records (“it can’t find records with the same name has the computers stored on it”)
B11: #5 | C11: Escalate the line availability to the providers | H11: Oct22#2 & Dec22#2 & Jan23#2 Feb23#2 | I11: 45107 | J11: S.Sawluk | K11: 13.01.23 Same Correvtive Action as in Oct, due date 31.12.=> 31.01.23 15.02.23 Same corrective Action as in Oct&Dev 03.07.2023 Same incident occurring in the actual month | L11: Power and ISP outages are causing service interruption in Network & Connectivity, no continuity/redundancy working properly
B12: #6
B13: #7 | C13: Make sure all configuration and services are working in a proper way after a planned maintenance | H13: Dec22#3 | I13: 45107 | J13: M.Ben-Khaled | K13: 03.07.2023 Change Proccess Alingment must be in place | L13: Old processes denies job run properly
B14: #8 | C14: Check in daily basis events sent from our monitoring systems | H14: Mar23#2 | I14: 45107 | J14: B.Meier | L14: Physical equipment’s were affected due faulty disk or misconfigurations
B15: #9
B16: #10
B17: #11
B18: #12
B22: Closed actions: | H22: Root Cause # | I22: Due Date | J22: Responsible | K22: Action closure reportered in | L22: Root Cause description
B24: #1: | C24: Change Request has been created for the equipment replacement CHG0038972. Switch replacement was successfully done. | H24: Oct21 - #4 | I24: 44494 | J24: S. Montoya | K24: 44470
B25: #2: | C25: Rebuild the Storage device without damaged disks, restore data and production environment from backups. | H25: Nov21 - #10 | I25: 44526 | J25: A.Steelman | K25: 44501
B26: #3: | C26: Problem with entering Internet Access (WebAccess)( CHG0039207) | H26: Nov21 - #3 | I26: 44512 | J26: B.Besslein | K26: 44502
B27: #4: | C27: Configuration awareness provided to the users to avoid the missconfiguration of the system | H27: Nov21 - #2 | I27: 44503 | J27: S.Pietsch | K27: 44503
B28: #5: | C28: Collaborate with involved stakeholders during Change Management process. | H28: Oct21 - #4 | I28: 44561 | J28: S.Sawluk
B29: #6: | C29: Collaborate with involved stakeholders during Change Management process. | H29: Nov21 - #5 | I29: 44561 | J29: B. Meier
B30: #7: | C30: Provide guideness to users about It Incident and Change Management | H30: Nov21 - #6 | I30: 44561 | J30: I.Aguir
B31: #8: | C31: Followup meeting is scheduled to continue working on the 5W analysis with different parts | H31: Nov21 - #9 | I31: 44561 | J31: M. Ben Khaled
B32: #9: | C32: Additional ONTAP upgrade on all clustered LEONI NetApp systems due to annoying bugs and CVE-2021-27001 (CHG0038953) | H32: Nov21 - #5 | I32: 44537 | J32: A.Dicker
B33: #10: | C33: CAB meetings should be schedule by Service to inform, discuss and approve the changes to avoid failures and impact on the business | H33: Sep21 - #5 | I33: 44561 | J33: T. Ben Hnia
B34: #11: | C34: Roll back to old connection between TN3 & TN4 was in place. This issue will be solved permenantly when the SDWAN migration will be in place in TN3 | H34: #2 | I34: 44613 | J34: Amel Ben Hassine | K34: Feb-22
B35: #12: | C35: Corrective action must be work in the PRB0040153: Fix was applied and the problem was closed. | H35: #3 | I35: 44615 | J35: Ilyess Lagha | K35: Feb-22
B36: #13: | C36: Solution: new image has beeen uploades and tested. CHG0039968 | H36: #5 | I36: 44604 | J36: Santiago Montoya | K36: Feb-22
B37: #14: | C37: CHG0039486 has been raised to fix the incident | H37: #7 | I37: 44594 | J37: Amel Ben Hassine | K37: Feb-22
B38: #15: | C38: PRB0040118: problem still in root cause analysis Issue solved by workarround | H38: Jan22#2 | I38: 44619 | J38: A. Azouz | K38: 44562
B39: #16: | C39: Provide guideness regarding Problem Management and incident management processes | H39: Jan22#2 Jan22#5 | I39: 44620 | J39: I.Aguir | K39: 44562
B40: #17: | C40: Backups rerouted to another backup device. | H40: Apr22 #3 | I40: 44670 | J40: Andreas Zierott | K40: 44652
B41: #18: | C41: VMs have been migrated to EXPY1001 in order to reboot EXPY1002, after reboot SQL01 turned on | H41: Apr22 #4 | I41: 44672 | J41: Ricardo Rico Montano | K41: 44652
B42: #19: | C42: Workarround: Network has been restored, Permenant Solution: Firmware upgraded from 9.1.8 to latest recommended release 9.1.13-h3 ( PRB0040251) | H42: Apr22 #6 | I42: 44679 | J42: Andreas Thanner | K42: 44652
B43: #20: | C43: All applied actions are detailed into the Problem PRB0040146 | H43: Apr22#1 | I43: 44742 | J43: Anders Dicker | K43: 44683
B44: 21 | C44: All applied actions are detailed into the Problem PRB0040232 | J44: Andreas Thanner | K44: 44714
B45: 22 | C45: All applied actions are detailed into the Problem PRB0040264-PRB0040265 | H45: May22#2 | I45: 44772 | J45: Stefan Sawluk | K45: 44714
B46: 23 | C46: Correction of new rule implemented | H46: May22#1 | I46: 44772 | J46: Amel Ben Hassine | K46: 44714
...
